Workbook

Sheet PriceData
A1: Date | B1: AAPL | C1: MSFT | D1: GOOGL | E1: AMZN | F1: JPM | G1: BAC | H1: JNJ | I1: UNH | J1: XOM | K1: CVX | L1: PG | M1: KO | N1: NEE | O1: DUK | P1: AMT | Q1: PLD | R1: CAT | S1: HON
A2: 44256 | B2: 118.9736 | C2: 226.2354 | D2: 102.3527 | E2: 154.704 | F2: 134.0578 | G2: 34.2884 | H2: 143.4774 | I2: 342.951 | J2: 46.0981 | K2: 85.0937 | L2: 119.3778 | M2: 45.3489 | N2: 66.8841 | O2: 79.4995 | P2: 206.4244 | Q2: 92.1463 | R2: 211.4677 | S2: 185.5713
A3: 44287 | B3: 128.0415 | C3: 241.9817 | D3: 116.7925 | E3: 173.371 | F3: 135.4492 | G3: 36.0975 | H3: 142.0631 | I3: 368.8948 | J3: 47.2623 | K3: 83.697 | L3: 117.606 | M3: 46.8281 | N3: 68.5648 | O3: 82.9256 | P3: 219.9897 | Q3: 101.929 | R3: 208.0385 | S3: 190.675
A4: 44317 | B4: 121.3696 | C4: 239.5828 | D4: 116.9588 | E4: 161.1535 | F4: 145.486 | G4: 37.7541 | H4: 147.755 | I4: 381.0311 | J4: 48.1953 | K4: 84.2817 | L4: 119.627 | M4: 47.9646 | N4: 64.7699 | O4: 82.5385 | P4: 221.7293 | Q4: 103.0749 | R4: 220.8611 | S4: 197.4029
A5: 44348 | B5: 133.625 | C5: 260.545 | D5: 121.174 | E5: 172.008 | F5: 137.7794 | G5: 36.721 | H5: 144.7151 | I5: 370.4119 | J5: 52.8431 | K5: 86.0942 | L5: 119.698 | M5: 46.9409 | N5: 64.823 | O5: 82.0858 | P5: 234.471 | Q5: 104.5531 | R5: 199.3778 | S5: 188.3163
A6: 44378 | B6: 142.3083 | C6: 274.0194 | D6: 133.7162 | E6: 166.3795 | F6: 134.4487 | G6: 34.3087 | H6: 151.2683 | I6: 382.7052 | J6: 48.2272 | K6: 83.6858 | L6: 126.174 | M6: 49.8468 | N6: 69.274 | O6: 87.399 | P6: 246.6345 | Q6: 112.5589 | R6: 189.4103 | S6: 200.7133
A7: 44409 | B7: 148.1329 | C7: 290.3408 | D7: 143.6124 | E7: 173.5395 | F7: 142.5023 | G7: 37.3406 | H7: 152.0853 | I7: 386.4651 | J7: 45.6722 | K7: 79.543 | L7: 127.1103 | M7: 49.2175 | N7: 74.6897 | O7: 87.0249 | P7: 254.8062 | Q7: 118.3785 | R7: 194.2215 | S7: 199.0993
A8: 44440 | B8: 138.2613 | C8: 271.6628 | D8: 132.6736 | E8: 164.252 | F8: 145.8343 | G8: 37.9667 | H8: 142.712 | I8: 362.763 | J8: 50.0202 | K8: 84.5142 | L8: 124.7983 | M8: 45.8612 | N8: 70.1449 | O8: 81.8991 | P8: 231.4684 | Q8: 110.2645 | R8: 176.8137 | S8: 182.9732
A9: 44470 | B9: 146.3713 | C9: 319.5546 | D9: 146.9358 | E9: 168.6215 | F9: 151.358 | G9: 42.9528 | H9: 143.9314 | I9: 429.001 | J9: 54.8249 | K9: 95.3773 | L9: 127.6459 | M9: 49.6418 | N9: 76.2285 | O9: 85.6085 | P9: 247.0576 | Q9: 128.0384 | R9: 187.9031 | S9: 188.4379
A10: 44501 | B10: 161.5166 | C10: 318.562 | D10: 140.8334 | E10: 175.3535 | F10: 142.3571 | G10: 39.9772 | H10: 137.7899 | I10: 413.8615 | J10: 50.8876 | K10: 94.0278 | L10: 129.8654 | M10: 46.1897 | N10: 77.5238 | O10: 81.4124 | P10: 229.9808 | Q10: 133.1524 | R10: 179.068 | S10: 174.3194
A11: 44531 | B11: 173.759 | C11: 324.6765 | D11: 143.7657 | E11: 166.717 | F11: 141.927 | G11: 39.9952 | H11: 152.1588 | I11: 467.8232 | J11: 52.7349 | K11: 98.8898 | L11: 146.9317 | M11: 52.5472 | N11: 83.7714 | O11: 88.8925 | P11: 256.2838 | Q11: 148.7067 | R11: 191.4689 | S11: 180.5004
A12: 44562 | B12: 171.0288 | C12: 300.2138 | D12: 134.2889 | E12: 149.5735 | F12: 133.1882 | G12: 41.6781 | H12: 153.244 | I12: 441.71 | J12: 65.4641 | K12: 110.6706 | L12: 144.1202 | M12: 54.1446 | N12: 70.0966 | O12: 89.0281 | P12: 221.4548 | Q12: 139.0646 | R12: 186.6716 | S12: 177.0118
A13: 44593 | B13: 161.5762 | C13: 288.4458 | D13: 134.0442 | E13: 153.563 | F13: 127.8552 | G13: 39.9257 | H13: 146.3774 | I13: 444.7945 | J13: 67.5842 | K13: 121.3475 | L13: 140.7804 | M13: 55.2362 | N13: 70.2312 | O13: 85.0877 | P13: 199.7671 | Q13: 129.3367 | R13: 174.5672 | S13: 164.2605
... A61: 46054 | B61: 266.18 | C61: 384.47 | D61: 311.49 | E61: 205.27 | F61: 297.67 | G61: 51.07 | H61: 245.84 | I61: 282.34 | J61: 150.76 | K61: 184.91 | L61: 165.17 | M61: 80.56 | N61: 94.06 | O61: 127.79 | P61: 190.05 | Q61: 140.74 | R61: 756.47 | S61: 243.06

Sheet Monthly Returns
A1: Date | B1: AAPL | C1: MSFT | D1: GOOGL | E1: AMZN | F1: JPM | G1: BAC | H1: JNJ | I1: UNH | J1: XOM | K1: CVX | L1: PG | M1: KO | N1: NEE | O1: DUK | P1: AMT | Q1: PLD | R1: CAT | S1: HON
A2: 44256
A3: 44287 | B3: =(PriceData!B3-PriceData!B2)/PriceData!B2 -> 0.076217749 | C3: =(PriceData!C3-PriceData!C2)/PriceData!C2 -> 0.069601397 | D3: =(PriceData!D3-PriceData!D2)/PriceData!D2 -> 0.14107884 | E3: =(PriceData!E3-PriceData!E2)/PriceData!E2 -> 0.12066268 | F3: =(PriceData!F3-PriceData!F2)/PriceData!F2 -> 0.010379105 | G3: =(PriceData!G3-PriceData!G2)/PriceData!G2 -> 0.052761284 | H3: =(PriceData!H3-PriceData!H2)/PriceData!H2 -> -0.0098573016 | I3: =(PriceData!I3-PriceData!I2)/PriceData!I2 -> 0.075648708 | ... S3: =(PriceData!S3-PriceData!S2)/PriceData!S2 -> 0.027502636
A4: 44317 | B4: =(PriceData!B4-PriceData!B3)/PriceData!B3 -> -0.052107325 | C4: =(PriceData!C4-PriceData!C3)/PriceData!C3 -> -0.0099135596 | D4: =(PriceData!D4-PriceData!D3)/PriceData!D3 -> 0.0014238928 | E4: =(PriceData!E4-PriceData!E3)/PriceData!E3 -> -0.070470263 | F4: =(PriceData!F4-PriceData!F3)/PriceData!F3 -> 0.074100105 | G4: =(PriceData!G4-PriceData!G3)/PriceData!G3 -> 0.045892375 | H4: =(PriceData!H4-PriceData!H3)/PriceData!H3 -> 0.040065999 | I4: =(PriceData!I4-PriceData!I3)/PriceData!I3 -> 0.032899081 | ... S4: =(PriceData!S4-PriceData!S3)/PriceData!S3 -> 0.035284647
A5: 44348 | B5: =(PriceData!B5-PriceData!B4)/PriceData!B4 -> 0.10097586 | C5: =(PriceData!C5-PriceData!C4)/PriceData!C4 -> 0.087494595 | D5: =(PriceData!D5-PriceData!D4)/PriceData!D4 -> 0.036040041 | E5: =(PriceData!E5-PriceData!E4)/PriceData!E4 -> 0.067355037 | F5: =(PriceData!F5-PriceData!F4)/PriceData!F4 -> -0.05297142 | G5: =(PriceData!G5-PriceData!G4)/PriceData!G4 -> -0.027363915 | H5: =(PriceData!H5-PriceData!H4)/PriceData!H4 -> -0.020573923 | I5: =(PriceData!I5-PriceData!I4)/PriceData!I4 -> -0.027869641 | ... S5: =(PriceData!S5-PriceData!S4)/PriceData!S4 -> -0.046030732
A6: 44378 | B6: =(PriceData!B6-PriceData!B5)/PriceData!B5 -> 0.064982601 | C6: =(PriceData!C6-PriceData!C5)/PriceData!C5 -> 0.05171621 | D6: =(PriceData!D6-PriceData!D5)/PriceData!D5 -> 0.1035057 | E6: =(PriceData!E6-PriceData!E5)/PriceData!E5 -> -0.032722315 | F6: =(PriceData!F6-PriceData!F5)/PriceData!F5 -> -0.024174151 | G6: =(PriceData!G6-PriceData!G5)/PriceData!G5 -> -0.065692655 | H6: =(PriceData!H6-PriceData!H5)/PriceData!H5 -> 0.045283457 | I6: =(PriceData!I6-PriceData!I5)/PriceData!I5 -> 0.033188189 | ... S6: =(PriceData!S6-PriceData!S5)/PriceData!S5 -> 0.065830733
A7: 44409 | B7: =(PriceData!B7-PriceData!B6)/PriceData!B6 -> 0.040929447 | C7: =(PriceData!C7-PriceData!C6)/PriceData!C6 -> 0.059562936 | D7: =(PriceData!D7-PriceData!D6)/PriceData!D6 -> 0.074008983 | E7: =(PriceData!E7-PriceData!E6)/PriceData!E6 -> 0.043034148 | F7: =(PriceData!F7-PriceData!F6)/PriceData!F6 -> 0.059900914 | G7: =(PriceData!G7-PriceData!G6)/PriceData!G6 -> 0.088371171 | H7: =(PriceData!H7-PriceData!H6)/PriceData!H6 -> 0.0054009994 | I7: =(PriceData!I7-PriceData!I6)/PriceData!I6 -> 0.0098245333 | ... S7: =(PriceData!S7-PriceData!S6)/PriceData!S6 -> -0.0080413206
A8: 44440 | B8: =(PriceData!B8-PriceData!B7)/PriceData!B7 -> -0.066640159 | C8: =(PriceData!C8-PriceData!C7)/PriceData!C7 -> -0.064331296 | D8: =(PriceData!D8-PriceData!D7)/PriceData!D7 -> -0.07616891 | E8: =(PriceData!E8-PriceData!E7)/PriceData!E7 -> -0.053518075 | F8: =(PriceData!F8-PriceData!F7)/PriceData!F7 -> 0.023382079 | G8: =(PriceData!G8-PriceData!G7)/PriceData!G7 -> 0.016767272 | H8: =(PriceData!H8-PriceData!H7)/PriceData!H7 -> -0.061631861 | I8: =(PriceData!I8-PriceData!I7)/PriceData!I7 -> -0.061330506 | ... S8: =(PriceData!S8-PriceData!S7)/PriceData!S7 -> -0.080995262
A9: 44470 | B9: =(PriceData!B9-PriceData!B8)/PriceData!B8 -> 0.05865705 | C9: =(PriceData!C9-PriceData!C8)/PriceData!C8 -> 0.17629134 | D9: =(PriceData!D9-PriceData!D8)/PriceData!D8 -> 0.1074984 | E9: =(PriceData!E9-PriceData!E8)/PriceData!E8 -> 0.026602416 | F9: =(PriceData!F9-PriceData!F8)/PriceData!F8 -> 0.037876549 | G9: =(PriceData!G9-PriceData!G8)/PriceData!G8 -> 0.13132824 | H9: =(PriceData!H9-PriceData!H8)/PriceData!H8 -> 0.0085444812 | I9: =(PriceData!I9-PriceData!I8)/PriceData!I8 -> 0.18259304 | ... S9: =(PriceData!S9-PriceData!S8)/PriceData!S8 -> 0.029866122
A10: 44501 | B10: =(PriceData!B10-PriceData!B9)/PriceData!B9 -> 0.10347179 | C10: =(PriceData!C10-PriceData!C9)/PriceData!C9 -> -0.0031061984 | D10: =(PriceData!D10-PriceData!D9)/PriceData!D9 -> -0.041531063 | E10: =(PriceData!E10-PriceData!E9)/PriceData!E9 -> 0.039923735 | F10: =(PriceData!F10-PriceData!F9)/PriceData!F9 -> -0.05946762 | G10: =(PriceData!G10-PriceData!G9)/PriceData!G9 -> -0.069276043 | H10: =(PriceData!H10-PriceData!H9)/PriceData!H9 -> -0.042669633 | I10: =(PriceData!I10-PriceData!I9)/PriceData!I9 -> -0.035290128 | ... S10: =(PriceData!S10-PriceData!S9)/PriceData!S9 -> -0.074923887
A11: 44531 | B11: =(PriceData!B11-PriceData!B10)/PriceData!B10 -> 0.075796544 | C11: =(PriceData!C11-PriceData!C10)/PriceData!C10 -> 0.019194066 | D11: =(PriceData!D11-PriceData!D10)/PriceData!D10 -> 0.020821055 | E11: =(PriceData!E11-PriceData!E10)/PriceData!E10 -> -0.04925194 | F11: =(PriceData!F11-PriceData!F10)/PriceData!F10 -> -0.0030212754 | G11: =(PriceData!G11-PriceData!G10)/PriceData!G10 -> 0.00045025665 | H11: =(PriceData!H11-PriceData!H10)/PriceData!H10 -> 0.10428123 | I11: =(PriceData!I11-PriceData!I10)/PriceData!I10 -> 0.13038589 | ... S11: =(PriceData!S11-PriceData!S10)/PriceData!S10 -> 0.035457901
A12: 44562 | B12: =(PriceData!B12-PriceData!B11)/PriceData!B11 -> -0.015712567 | C12: =(PriceData!C12-PriceData!C11)/PriceData!C11 -> -0.075344843 | D12: =(PriceData!D12-PriceData!D11)/PriceData!D11 -> -0.065918366 | E12: =(PriceData!E12-PriceData!E11)/PriceData!E11 -> -0.10282995 | F12: =(PriceData!F12-PriceData!F11)/PriceData!F11 -> -0.061572499 | G12: =(PriceData!G12-PriceData!G11)/PriceData!G11 -> 0.042077549 | H12: =(PriceData!H12-PriceData!H11)/PriceData!H11 -> 0.0071320226 | I12: =(PriceData!I12-PriceData!I11)/PriceData!I11 -> -0.055818523 | ... S12: =(PriceData!S12-PriceData!S11)/PriceData!S11 -> -0.019327381
A13: 44593 | B13: =(PriceData!B13-PriceData!B12)/PriceData!B12 -> -0.055269054 | C13: =(PriceData!C13-PriceData!C12)/PriceData!C12 -> -0.039198731 | D13: =(PriceData!D13-PriceData!D12)/PriceData!D12 -> -0.0018221908 | E13: =(PriceData!E13-PriceData!E12)/PriceData!E12 -> 0.026672505 | F13: =(PriceData!F13-PriceData!F12)/PriceData!F12 -> -0.040041085 | G13: =(PriceData!G13-PriceData!G12)/PriceData!G12 -> -0.042046063 | H13: =(PriceData!H13-PriceData!H12)/PriceData!H12 -> -0.04480828 | I13: =(PriceData!I13-PriceData!I12)/PriceData!I12 -> 0.0069830885 | ... S13: =(PriceData!S13-PriceData!S12)/PriceData!S12 -> -0.072036441
A14: 44621 | B14: =(PriceData!B14-PriceData!B13)/PriceData!B13 -> 0.058820544 | C14: =(PriceData!C14-PriceData!C13)/PriceData!C13 -> 0.033995295 | D14: =(PriceData!D14-PriceData!D13)/PriceData!D13 -> 0.029694683 | E14: =(PriceData!E14-PriceData!E13)/PriceData!E13 -> 0.061437325 | F14: =(PriceData!F14-PriceData!F13)/PriceData!F13 -> -0.03864528 | G14: =(PriceData!G14-PriceData!G13)/PriceData!G13 -> -0.067420233 | H14: =(PriceData!H14-PriceData!H13)/PriceData!H13 -> 0.083840811 | I14: =(PriceData!I14-PriceData!I13)/PriceData!I13 -> 0.07165826 | ... S14: =(PriceData!S14-PriceData!S13)/PriceData!S13 -> 0.031100599
... A61: 46054 | B61: =(PriceData!B61-PriceData!B60)/PriceData!B60 -> 0.026780858 | C61: =(PriceData!C61-PriceData!C60)/PriceData!C60 -> -0.10444688 | D61: =(PriceData!D61-PriceData!D60)/PriceData!D60 -> -0.078431953 | E61: =(PriceData!E61-PriceData!E60)/PriceData!E60 -> -0.14220644 | F61: =(PriceData!F61-PriceData!F60)/PriceData!F60 -> -0.022482861 | G61: =(PriceData!G61-PriceData!G60)/PriceData!G60 -> -0.040037594 | H61: =(PriceData!H61-PriceData!H60)/PriceData!H60 -> 0.08180418 | I61: =(PriceData!I61-PriceData!I60)/PriceData!I60 -> -0.015996933 | ... S61: =(PriceData!S61-PriceData!S60)/PriceData!S60 -> 0.068301688

Sheet Stock Analytics
A1: STOCK ANALYTICS — RISK & RETURN SUMMARY
A2: Risk-Free Rate | B2: 0.0425
A4: Ticker | B4: Company | C4: Sector | D4: Avg Monthly Return | E4: Annualized Return | F4: Monthly Volatility | G4: Annualized Volatility | H4: Sharpe Ratio
A5: AAPL | B5: Apple Inc. | C5: Technology | D5: =AVERAGE('Monthly Returns'!B3:B61) -> 0.016155056 | E5: =(1+D5)^12-1 -> 0.21204791 | F5: =STDEV('Monthly Returns'!B3:B61) -> 0.070615334 | G5: =F5*SQRT(12) -> 0.24461869 | H5: =(E5-$B$2)/G5 -> 0.693111
A6: MSFT | B6: Microsoft Corp. | C6: Technology | D6: =AVERAGE('Monthly Returns'!C3:C61) -> 0.011291202 | E6: =(1+D6)^12-1 -> 0.14423374 | F6: =STDEV('Monthly Returns'!C3:C61) -> 0.068520488 | G6: =F6*SQRT(12) -> 0.23736193 | H6: =(E6-$B$2)/G6 -> 0.42860176
A7: GOOGL | B7: Alphabet Inc. | C7: Technology | D7: =AVERAGE('Monthly Returns'!D3:D61) -> 0.022386387 | E7: =(1+D7)^12-1 -> 0.30430962 | F7: =STDEV('Monthly Returns'!D3:D61) -> 0.08231633 | G7: =F7*SQRT(12) -> 0.28515213 | H7: =(E7-$B$2)/G7 -> 0.91814015
A8: AMZN | B8: Amazon.com Inc. | C8: Consumer Disc. | D8: =AVERAGE('Monthly Returns'!E3:E61) -> 0.0089540515 | E8: =(1+D8)^12-1 -> 0.11290133 | F8: =STDEV('Monthly Returns'!E3:E61) -> 0.09220028 | G8: =F8*SQRT(12) -> 0.31939114 | H8: =(E8-$B$2)/G8 -> 0.22042357
A9: JPM | B9: JPMorgan Chase | C9: Financials | D9: =AVERAGE('Monthly Returns'!F3:F61) -> 0.015905325 | E9: =(1+D9)^12-1 -> 0.20847825 | F9: =STDEV('Monthly Returns'!F3:F61) -> 0.068795867 | G9: =F9*SQRT(12) -> 0.23831587 | H9: =(E9-$B$2)/G9 -> 0.69646328
A10: BAC | B10: Bank of America | C10: Financials | D10: =AVERAGE('Monthly Returns'!G3:G61) -> 0.0098279143 | E10: =(1+D10)^12-1 -> 0.1245233 | F10: =STDEV('Monthly Returns'!G3:G61) -> 0.078796153 | G10: =F10*SQRT(12) -> 0.27295788 | H10: =(E10-$B$2)/G10 -> 0.30049801
A11: JNJ | B11: Johnson & Johnson | C11: Healthcare | D11: =AVERAGE('Monthly Returns'!H3:H61) -> 0.010338542 | E11: =(1+D11)^12-1 -> 0.1313658 | F11: =STDEV('Monthly Returns'!H3:H61) -> 0.049033059 | G11: =F11*SQRT(12) -> 0.1698555 | H11: =(E11-$B$2)/G11 -> 0.52318471
A12: UNH | B12: UnitedHealth Group | C12: Healthcare | D12: =AVERAGE('Monthly Returns'!I3:I61) -> 0.00068562793 | E12: =(1+D12)^12-1 -> 0.0082586318 | F12: =STDEV('Monthly Returns'!I3:I61) -> 0.08826035 | G12: =F12*SQRT(12) -> 0.30574282 | H12: =(E12-$B$2)/G12 -> -0.11199402
A13: XOM | B13: Exxon Mobil | C13: Energy | D13: =AVERAGE('Monthly Returns'!J3:J61) -> 0.023043384 | E13: =(1+D13)^12-1 -> 0.31440322 | F13: =STDEV('Monthly Returns'!J3:J61) -> 0.076698206 | G13: =F13*SQRT(12) -> 0.26569038 | H13: =(E13-$B$2)/G13 -> 1.0233838
A14: CVX | B14: Chevron Corp. | C14: Energy | D14: =AVERAGE('Monthly Returns'!K3:K61) -> 0.016219693 | E14: =(1+D14)^12-1 -> 0.21297341 | F14: =STDEV('Monthly Returns'!K3:K61) -> 0.078150815 | G14: =F14*SQRT(12) -> 0.27072236 | H14: =(E14-$B$2)/G14 -> 0.62969831
A15: PG | B15: Procter & Gamble | C15: Consumer Staples | D15: =AVERAGE('Monthly Returns'!L3:L61) -> 0.0067515289 | E15: =(1+D15)^12-1 -> 0.08409558 | F15: =STDEV('Monthly Returns'!L3:L61) -> 0.050465635 | G15: =F15*SQRT(12) -> 0.17481809 | H15: =(E15-$B$2)/G15 -> 0.23793636
A16: KO | B16: Coca-Cola Co. | C16: Consumer Staples | D16: =AVERAGE('Monthly Returns'!M3:M61) -> 0.010932754 | E16: =(1+D16)^12-1 -> 0.13937638 | F16: =STDEV('Monthly Returns'!M3:M61) -> 0.048582242 | G16: =F16*SQRT(12) -> 0.16829382 | H16: =(E16-$B$2)/G16 -> 0.57563837
A17: NEE | B17: NextEra Energy | C17: Utilities | D17: =AVERAGE('Monthly Returns'!N3:N61) -> 0.0085290934 | E17: =(1+D17)^12-1 -> 0.10728947 | F17: =STDEV('Monthly Returns'!N3:N61) -> 0.074305266 | G17: =F17*SQRT(12) -> 0.25740099 | H17: =(E17-$B$2)/G17 -> 0.25170639
A18: DUK | B18: Duke Energy | C18: Utilities | D18: =AVERAGE('Monthly Returns'!O3:O61) -> 0.0091813338 | E18: =(1+D18)^12-1 -> 0.11591344 | F18: =STDEV('Monthly Returns'!O3:O61) -> 0.047279684 | G18: =F18*SQRT(12) -> 0.16378163 | H18: =(E18-$B$2)/G18 -> 0.44823977
A19: AMT | B19: American Tower | C19: Real Estate | D19: =AVERAGE('Monthly Returns'!P3:P61) -> 0.0014726817 | E19: =(1+D19)^12-1 -> 0.017816025 | F19: =STDEV('Monthly Returns'!P3:P61) -> 0.076364714 | G19: =F19*SQRT(12) -> 0.26453513 | H19: =(E19-$B$2)/G19 -> -0.093310764
A20: PLD | B20: Prologis Inc. | C20: Real Estate | D20: =AVERAGE('Monthly Returns'!Q3:Q61) -> 0.01107017 | E20: =(1+D20)^12-1 -> 0.14123628 | F20: =STDEV('Monthly Returns'!Q3:Q61) -> 0.087755711 | G20: =F20*SQRT(12) -> 0.3039947 | H20: =(E20-$B$2)/G20 -> 0.32479604
A21: CAT | B21: Caterpillar Inc. | C21: Industrials | D21: =AVERAGE('Monthly Returns'!R3:R61) -> 0.026522129 | E21: =(1+D21)^12-1 -> 0.36905151 | F21: =STDEV('Monthly Returns'!R3:R61) -> 0.09964912 | G21: =F21*SQRT(12) -> 0.34519468 | H21: =(E21-$B$2)/G21 -> 0.94599232
A22: HON | B22: Honeywell Intl. | C22: Industrials | D22: =AVERAGE('Monthly Returns'!S3:S61) -> 0.0064865008 | E22: =(1+D22)^12-1 -> 0.080675867 | F22: =STDEV('Monthly Returns'!S3:S61) -> 0.063349797 | G22: =F22*SQRT(12) -> 0.21945013 | H22: =(E22-$B$2)/G22 -> 0.17396147

Sheet Correlation Matrix
A1: CORRELATION MATRIX
B3: AAPL | C3: MSFT | D3: GOOGL | E3: AMZN | F3: JPM | G3: BAC | H3: JNJ | I3: UNH | J3: XOM | K3: CVX | L3: PG | M3: KO | N3: NEE | O3: DUK | P3: AMT | Q3: PLD | R3: CAT | S3: HON
A4: AAPL | B4: =CORREL(INDEX('Monthly Returns'!$B$3:$S$61,0,COLUMN()-1),INDEX('Monthly Returns'!$B$3:$S$61,0,ROW()-3)) -> 1 | C4: =CORREL(INDEX('Monthly Returns'!$B$3:$S$61,0,COLUMN()-1),INDEX('Monthly Returns'!$B$3:$S$61,0,ROW()-3)) -> 0.48681264 | D4: =CORREL(INDEX('Monthly Returns'!$B$3:$S$61,0,COLUMN()-1),INDEX('Monthly Returns'!$B$3:$S$61,0,ROW()-3)) -> 0.48085301 | E4: =CORREL(INDEX('Monthly Returns'!$B$3:$S$61,0,COLUMN()-1),INDEX('Monthly Returns'!$B$3:$S$61,0,ROW()-3)) -> 0.52759873 | F4: =CORREL(INDEX('Monthly Returns'!$B$3:$S$61,0,COLUMN()-1),INDEX('Monthly Returns'!$B$3:$S$61,0,ROW()-3)) -> 0.22530481 | G4: =CORREL(INDEX('Monthly Returns'!$B$3:$S$61,0,COLUMN()-1),INDEX('Monthly Returns'!$B$3:$S$61,0,ROW()-3)) -> 0.34964666 | H4: =CORREL(INDEX('Monthly Returns'!$B$3:$S$61,0,COLUMN()-1),INDEX('Monthly Returns'!$B$3:$S$61,0,ROW()-3)) -> 0.18008537 | I4: =CORREL(INDEX('Monthly Returns'!$B$3:$S$61,0,COLUMN()-1),INDEX('Monthly Returns'!$B$3:$S$61,0,ROW()-3)) -> 0.31174768 | ... S4: =CORREL(INDEX('Monthly Returns'!$B$3:$S$61,0,COLUMN()-1),INDEX('Monthly Returns'!$B$3:$S$61,0,ROW()-3)) -> 0.31800076
A5: MSFT | B5: =CORREL(INDEX('Monthly Returns'!$B$3:$S$61,0,COLUMN()-1),INDEX('Monthly Returns'!$B$3:$S$61,0,ROW()-3)) -> 0.48681264 | C5: =CORREL(INDEX('Monthly Returns'!$B$3:$S$61,0,COLUMN()-1),INDEX('Monthly Returns'!$B$3:$S$61,0,ROW()-3)) -> 1 | D5: =CORREL(INDEX('Monthly Returns'!$B$3:$S$61,0,COLUMN()-1),INDEX('Monthly Returns'!$B$3:$S$61,0,ROW()-3)) -> 0.51614627 | E5: =CORREL(INDEX('Monthly Returns'!$B$3:$S$61,0,COLUMN()-1),INDEX('Monthly Returns'!$B$3:$S$61,0,ROW()-3)) -> 0.62217589 | F5: =CORREL(INDEX('Monthly Returns'!$B$3:$S$61,0,COLUMN()-1),INDEX('Monthly Returns'!$B$3:$S$61,0,ROW()-3)) -> 0.32123993 | G5: =CORREL(INDEX('Monthly Returns'!$B$3:$S$61,0,COLUMN()-1),INDEX('Monthly Returns'!$B$3:$S$61,0,ROW()-3)) -> 0.31968206 | H5: =CORREL(INDEX('Monthly Returns'!$B$3:$S$61,0,COLUMN()-1),INDEX('Monthly Returns'!$B$3:$S$61,0,ROW()-3)) -> -0.076891369 | I5: =CORREL(INDEX('Monthly Returns'!$B$3:$S$61,0,COLUMN()-1),INDEX('Monthly Returns'!$B$3:$S$61,0,ROW()-3)) -> 0.013727561 | ... S5: =CORREL(INDEX('Monthly Returns'!$B$3:$S$61,0,COLUMN()-1),INDEX('Monthly Returns'!$B$3:$S$61,0,ROW()-3)) -> 0.28351404
A6: GOOGL | B6: =CORREL(INDEX('Monthly Returns'!$B$3:$S$61,0,COLUMN()-1),INDEX('Monthly Returns'!$B$3:$S$61,0,ROW()-3)) -> 0.48085301 | C6: =CORREL(INDEX('Monthly Returns'!$B$3:$S$61,0,COLUMN()-1),INDEX('Monthly Returns'!$B$3:$S$61,0,ROW()-3)) -> 0.51614627 | D6: =CORREL(INDEX('Monthly Returns'!$B$3:$S$61,0,COLUMN()-1),INDEX('Monthly Returns'!$B$3:$S$61,0,ROW()-3)) -> 1 | E6: =CORREL(INDEX('Monthly Returns'!$B$3:$S$61,0,COLUMN()-1),INDEX('Monthly Returns'!$B$3:$S$61,0,ROW()-3)) -> 0.63541674 | F6: =CORREL(INDEX('Monthly Returns'!$B$3:$S$61,0,COLUMN()-1),INDEX('Monthly Returns'!$B$3:$S$61,0,ROW()-3)) -> 0.23171887 | G6: =CORREL(INDEX('Monthly Returns'!$B$3:$S$61,0,COLUMN()-1),INDEX('Monthly Returns'!$B$3:$S$61,0,ROW()-3)) -> 0.32919219 | H6: =CORREL(INDEX('Monthly Returns'!$B$3:$S$61,0,COLUMN()-1),INDEX('Monthly Returns'!$B$3:$S$61,0,ROW()-3)) -> 0.027286927 | I6: =CORREL(INDEX('Monthly Returns'!$B$3:$S$61,0,COLUMN()-1),INDEX('Monthly Returns'!$B$3:$S$61,0,ROW()-3)) -> 0.059640878 | ... S6: =CORREL(INDEX('Monthly Returns'!$B$3:$S$61,0,COLUMN()-1),INDEX('Monthly Returns'!$B$3:$S$61,0,ROW()-3)) -> 0.18500213
A7: AMZN | B7: =CORREL(INDEX('Monthly Returns'!$B$3:$S$61,0,COLUMN()-1),INDEX('Monthly Returns'!$B$3:$S$61,0,ROW()-3)) -> 0.52759873 | C7: =CORREL(INDEX('Monthly Returns'!$B$3:$S$61,0,COLUMN()-1),INDEX('Monthly Returns'!$B$3:$S$61,0,ROW()-3)) -> 0.62217589 | D7: =CORREL(INDEX('Monthly Returns'!$B$3:$S$61,0,COLUMN()-1),INDEX('Monthly Returns'!$B$3:$S$61,0,ROW()-3)) -> 0.63541674 | E7: =CORREL(INDEX('Monthly Returns'!$B$3:$S$61,0,COLUMN()-1),INDEX('Monthly Returns'!$B$3:$S$61,0,ROW()-3)) -> 1 | F7: =CORREL(INDEX('Monthly Returns'!$B$3:$S$61,0,COLUMN()-1),INDEX('Monthly Returns'!$B$3:$S$61,0,ROW()-3)) -> 0.26205142 | G7: =CORREL(INDEX('Monthly Returns'!$B$3:$S$61,0,COLUMN()-1),INDEX('Monthly Returns'!$B$3:$S$61,0,ROW()-3)) -> 0.35128554 | H7: =CORREL(INDEX('Monthly Returns'!$B$3:$S$61,0,COLUMN()-1),INDEX('Monthly Returns'!$B$3:$S$61,0,ROW()-3)) -> -0.20038371 | I7: =CORREL(INDEX('Monthly Returns'!$B$3:$S$61,0,COLUMN()-1),INDEX('Monthly Returns'!$B$3:$S$61,0,ROW()-3)) -> -0.058059363 | ... S7: =CORREL(INDEX('Monthly Returns'!$B$3:$S$61,0,COLUMN()-1),INDEX('Monthly Returns'!$B$3:$S$61,0,ROW()-3)) -> 0.21223731
A8: JPM | B8: =CORREL(INDEX('Monthly Returns'!$B$3:$S$61,0,COLUMN()-1),INDEX('Monthly Returns'!$B$3:$S$61,0,ROW()-3)) -> 0.22530481 | C8: =CORREL(INDEX('Monthly Returns'!$B$3:$S$61,0,COLUMN()-1),INDEX('Monthly Returns'!$B$3:$S$61,0,ROW()-3)) -> 0.32123993 | D8: =CORREL(INDEX('Monthly Returns'!$B$3:$S$61,0,COLUMN()-1),INDEX('Monthly Returns'!$B$3:$S$61,0,ROW()-3)) -> 0.23171887 | E8: =CORREL(INDEX('Monthly Returns'!$B$3:$S$61,0,COLUMN()-1),INDEX('Monthly Returns'!$B$3:$S$61,0,ROW()-3)) -> 0.26205142 | F8: =CORREL(INDEX('Monthly Returns'!$B$3:$S$61,0,COLUMN()-1),INDEX('Monthly Returns'!$B$3:$S$61,0,ROW()-3)) -> 1 | G8: =CORREL(INDEX('Monthly Returns'!$B$3:$S$61,0,COLUMN()-1),INDEX('Monthly Returns'!$B$3:$S$61,0,ROW()-3)) -> 0.86239908 | H8: =CORREL(INDEX('Monthly Returns'!$B$3:$S$61,0,COLUMN()-1),INDEX('Monthly Returns'!$B$3:$S$61,0,ROW()-3)) -> 0.17904405 | I8: =CORREL(INDEX('Monthly Returns'!$B$3:$S$61,0,COLUMN()-1),INDEX('Monthly Returns'!$B$3:$S$61,0,ROW()-3)) -> 0.14889368 | ... S8: =CORREL(INDEX('Monthly Returns'!$B$3:$S$61,0,COLUMN()-1),INDEX('Monthly Returns'!$B$3:$S$61,0,ROW()-3)) -> 0.48584815
A9: BAC | B9: =CORREL(INDEX('Monthly Returns'!$B$3:$S$61,0,COLUMN()-1),INDEX('Monthly Returns'!$B$3:$S$61,0,ROW()-3)) -> 0.34964666 | C9: =CORREL(INDEX('Monthly Returns'!$B$3:$S$61,0,COLUMN()-1),INDEX('Monthly Returns'!$B$3:$S$61,0,ROW()-3)) -> 0.31968206 | D9: =CORREL(INDEX('Monthly Returns'!$B$3:$S$61,0,COLUMN()-1),INDEX('Monthly Returns'!$B$3:$S$61,0,ROW()-3)) -> 0.32919219 | E9: =CORREL(INDEX('Monthly Returns'!$B$3:$S$61,0,COLUMN()-1),INDEX('Monthly Returns'!$B$3:$S$61,0,ROW()-3)) -> 0.35128554 | F9: =CORREL(INDEX('Monthly Returns'!$B$3:$S$61,0,COLUMN()-1),INDEX('Monthly Returns'!$B$3:$S$61,0,ROW()-3)) -> 0.86239908 | G9: =CORREL(INDEX('Monthly Returns'!$B$3:$S$61,0,COLUMN()-1),INDEX('Monthly Returns'!$B$3:$S$61,0,ROW()-3)) -> 1 | H9: =CORREL(INDEX('Monthly Returns'!$B$3:$S$61,0,COLUMN()-1),INDEX('Monthly Returns'!$B$3:$S$61,0,ROW()-3)) -> 0.12755934 | I9: =CORREL(INDEX('Monthly Returns'!$B$3:$S$61,0,COLUMN()-1),INDEX('Monthly Returns'!$B$3:$S$61,0,ROW()-3)) -> 0.20713203 | ... S9: =CORREL(INDEX('Monthly Returns'!$B$3:$S$61,0,COLUMN()-1),INDEX('Monthly Returns'!$B$3:$S$61,0,ROW()-3)) -> 0.49861992
A10: JNJ | B10: =CORREL(INDEX('Monthly Returns'!$B$3:$S$61,0,COLUMN()-1),INDEX('Monthly Returns'!$B$3:$S$61,0,ROW()-3)) -> 0.18008537 | C10: =CORREL(INDEX('Monthly Returns'!$B$3:$S$61,0,COLUMN()-1),INDEX('Monthly Returns'!$B$3:$S$61,0,ROW()-3)) -> -0.076891369 | D10: =CORREL(INDEX('Monthly Returns'!$B$3:$S$61,0,COLUMN()-1),INDEX('Monthly Returns'!$B$3:$S$61,0,ROW()-3)) -> 0.027286927 | E10: =CORREL(INDEX('Monthly Returns'!$B$3:$S$61,0,COLUMN()-1),INDEX('Monthly Returns'!$B$3:$S$61,0,ROW()-3)) -> -0.20038371 | F10: =CORREL(INDEX('Monthly Returns'!$B$3:$S$61,0,COLUMN()-1),INDEX('Monthly Returns'!$B$3:$S$61,0,ROW()-3)) -> 0.17904405 | G10: =CORREL(INDEX('Monthly Returns'!$B$3:$S$61,0,COLUMN()-1),INDEX('Monthly Returns'!$B$3:$S$61,0,ROW()-3)) -> 0.12755934 | H10: =CORREL(INDEX('Monthly Returns'!$B$3:$S$61,0,COLUMN()-1),INDEX('Monthly Returns'!$B$3:$S$61,0,ROW()-3)) -> 1 | I10: =CORREL(INDEX('Monthly Returns'!$B$3:$S$61,0,COLUMN()-1),INDEX('Monthly Returns'!$B$3:$S$61,0,ROW()-3)) -> 0.26119331 | ... S10: =CORREL(INDEX('Monthly Returns'!$B$3:$S$61,0,COLUMN()-1),INDEX('Monthly Returns'!$B$3:$S$61,0,ROW()-3)) -> 0.35227386
A11: UNH | B11: =CORREL(INDEX('Monthly Returns'!$B$3:$S$61,0,COLUMN()-1),INDEX('Monthly Returns'!$B$3:$S$61,0,ROW()-3)) -> 0.31174768 | C11: =CORREL(INDEX('Monthly Returns'!$B$3:$S$61,0,COLUMN()-1),INDEX('Monthly Returns'!$B$3:$S$61,0,ROW()-3)) -> 0.013727561 | D11: =CORREL(INDEX('Monthly Returns'!$B$3:$S$61,0,COLUMN()-1),INDEX('Monthly Returns'!$B$3:$S$61,0,ROW()-3)) -> 0.059640878 | E11: =CORREL(INDEX('Monthly Returns'!$B$3:$S$61,0,COLUMN()-1),INDEX('Monthly Returns'!$B$3:$S$61,0,ROW()-3)) -> -0.058059363 | F11: =CORREL(INDEX('Monthly Returns'!$B$3:$S$61,0,COLUMN()-1),INDEX('Monthly Returns'!$B$3:$S$61,0,ROW()-3)) -> 0.14889368 | G11: =CORREL(INDEX('Monthly Returns'!$B$3:$S$61,0,COLUMN()-1),INDEX('Monthly Returns'!$B$3:$S$61,0,ROW()-3)) -> 0.20713203 | H11: =CORREL(INDEX('Monthly Returns'!$B$3:$S$61,0,COLUMN()-1),INDEX('Monthly Returns'!$B$3:$S$61,0,ROW()-3)) -> 0.26119331 | I11: =CORREL(INDEX('Monthly Returns'!$B$3:$S$61,0,COLUMN()-1),INDEX('Monthly Returns'!$B$3:$S$61,0,ROW()-3)) -> 1 | ... S11: =CORREL(INDEX('Monthly Returns'!$B$3:$S$61,0,COLUMN()-1),INDEX('Monthly Returns'!$B$3:$S$61,0,ROW()-3)) -> 0.13015965
A12: XOM | B12: =CORREL(INDEX('Monthly Returns'!$B$3:$S$61,0,COLUMN()-1),INDEX('Monthly Returns'!$B$3:$S$61,0,ROW()-3)) -> 0.062934441 | C12: =CORREL(INDEX('Monthly Returns'!$B$3:$S$61,0,COLUMN()-1),INDEX('Monthly Returns'!$B$3:$S$61,0,ROW()-3)) -> -0.16075759 | D12: =CORREL(INDEX('Monthly Returns'!$B$3:$S$61,0,COLUMN()-1),INDEX('Monthly Returns'!$B$3:$S$61,0,ROW()-3)) -> -0.10339919 | E12: =CORREL(INDEX('Monthly Returns'!$B$3:$S$61,0,COLUMN()-1),INDEX('Monthly Returns'!$B$3:$S$61,0,ROW()-3)) -> -0.073450115 | F12: =CORREL(INDEX('Monthly Returns'!$B$3:$S$61,0,COLUMN()-1),INDEX('Monthly Returns'!$B$3:$S$61,0,ROW()-3)) -> 0.21742536 | G12: =CORREL(INDEX('Monthly Returns'!$B$3:$S$61,0,COLUMN()-1),INDEX('Monthly Returns'!$B$3:$S$61,0,ROW()-3)) -> 0.35233135 | H12: =CORREL(INDEX('Monthly Returns'!$B$3:$S$61,0,COLUMN()-1),INDEX('Monthly Returns'!$B$3:$S$61,0,ROW()-3)) -> 0.28627892 | I12: =CORREL(INDEX('Monthly Returns'!$B$3:$S$61,0,COLUMN()-1),INDEX('Monthly Returns'!$B$3:$S$61,0,ROW()-3)) -> 0.16399211 | ... S12: =CORREL(INDEX('Monthly Returns'!$B$3:$S$61,0,COLUMN()-1),INDEX('Monthly Returns'!$B$3:$S$61,0,ROW()-3)) -> 0.42573431
A13: CVX | B13: =CORREL(INDEX('Monthly Returns'!$B$3:$S$61,0,COLUMN()-1),INDEX('Monthly Returns'!$B$3:$S$61,0,ROW()-3)) -> 0.17151719 | C13: =CORREL(INDEX('Monthly Returns'!$B$3:$S$61,0,COLUMN()-1),INDEX('Monthly Returns'!$B$3:$S$61,0,ROW()-3)) -> -0.044420497 | D13: =CORREL(INDEX('Monthly Returns'!$B$3:$S$61,0,COLUMN()-1),INDEX('Monthly Returns'!$B$3:$S$61,0,ROW()-3)) -> 0.0089020541 | E13: =CORREL(INDEX('Monthly Returns'!$B$3:$S$61,0,COLUMN()-1),INDEX('Monthly Returns'!$B$3:$S$61,0,ROW()-3)) -> 0.069589929 | F13: =CORREL(INDEX('Monthly Returns'!$B$3:$S$61,0,COLUMN()-1),INDEX('Monthly Returns'!$B$3:$S$61,0,ROW()-3)) -> 0.34394025 | G13: =CORREL(INDEX('Monthly Returns'!$B$3:$S$61,0,COLUMN()-1),INDEX('Monthly Returns'!$B$3:$S$61,0,ROW()-3)) -> 0.4401905 | H13: =CORREL(INDEX('Monthly Returns'!$B$3:$S$61,0,COLUMN()-1),INDEX('Monthly Returns'!$B$3:$S$61,0,ROW()-3)) -> 0.37114148 | I13: =CORREL(INDEX('Monthly Returns'!$B$3:$S$61,0,COLUMN()-1),INDEX('Monthly Returns'!$B$3:$S$61,0,ROW()-3)) -> 0.26101908 | ... S13: =CORREL(INDEX('Monthly Returns'!$B$3:$S$61,0,COLUMN()-1),INDEX('Monthly Returns'!$B$3:$S$61,0,ROW()-3)) -> 0.51391861
A14: PG | B14: =CORREL(INDEX('Monthly Returns'!$B$3:$S$61,0,COLUMN()-1),INDEX('Monthly Returns'!$B$3:$S$61,0,ROW()-3)) -> 0.17363751 | C14: =CORREL(INDEX('Monthly Returns'!$B$3:$S$61,0,COLUMN()-1),INDEX('Monthly Returns'!$B$3:$S$61,0,ROW()-3)) -> 0.15376584 | D14: =CORREL(INDEX('Monthly Returns'!$B$3:$S$61,0,COLUMN()-1),INDEX('Monthly Returns'!$B$3:$S$61,0,ROW()-3)) -> -0.078837667 | E14: =CORREL(INDEX('Monthly Returns'!$B$3:$S$61,0,COLUMN()-1),INDEX('Monthly Returns'!$B$3:$S$61,0,ROW()-3)) -> -0.16528284 | F14: =CORREL(INDEX('Monthly Returns'!$B$3:$S$61,0,COLUMN()-1),INDEX('Monthly Returns'!$B$3:$S$61,0,ROW()-3)) -> 0.14099898 | G14: =CORREL(INDEX('Monthly Returns'!$B$3:$S$61,0,COLUMN()-1),INDEX('Monthly Returns'!$B$3:$S$61,0,ROW()-3)) -> 0.12015542 | H14: =CORREL(INDEX('Monthly Returns'!$B$3:$S$61,0,COLUMN()-1),INDEX('Monthly Returns'!$B$3:$S$61,0,ROW()-3)) -> 0.43422238 | I14: =CORREL(INDEX('Monthly Returns'!$B$3:$S$61,0,COLUMN()-1),INDEX('Monthly Returns'!$B$3:$S$61,0,ROW()-3)) -> 0.19807286 | ... S14: =CORREL(INDEX('Monthly Returns'!$B$3:$S$61,0,COLUMN()-1),INDEX('Monthly Returns'!$B$3:$S$61,0,ROW()-3)) -> 0.4601605
A15: KO | B15: =CORREL(INDEX('Monthly Returns'!$B$3:$S$61,0,COLUMN()-1),INDEX('Monthly Returns'!$B$3:$S$61,0,ROW()-3)) -> 0.22177422 | C15: =CORREL(INDEX('Monthly Returns'!$B$3:$S$61,0,COLUMN()-1),INDEX('Monthly Returns'!$B$3:$S$61,0,ROW()-3)) -> 0.068412241 | D15: =CORREL(INDEX('Monthly Returns'!$B$3:$S$61,0,COLUMN()-1),INDEX('Monthly Returns'!$B$3:$S$61,0,ROW()-3)) -> 0.03655243 | E15: =CORREL(INDEX('Monthly Returns'!$B$3:$S$61,0,COLUMN()-1),INDEX('Monthly Returns'!$B$3:$S$61,0,ROW()-3)) -> -0.17057108 | F15: =CORREL(INDEX('Monthly Returns'!$B$3:$S$61,0,COLUMN()-1),INDEX('Monthly Returns'!$B$3:$S$61,0,ROW()-3)) -> 0.10701888 | G15: =CORREL(INDEX('Monthly Returns'!$B$3:$S$61,0,COLUMN()-1),INDEX('Monthly Returns'!$B$3:$S$61,0,ROW()-3)) -> 0.16692177 | H15: =CORREL(INDEX('Monthly Returns'!$B$3:$S$61,0,COLUMN()-1),INDEX('Monthly Returns'!$B$3:$S$61,0,ROW()-3)) -> 0.58737361 | I15: =CORREL(INDEX('Monthly Returns'!$B$3:$S$61,0,COLUMN()-1),INDEX('Monthly Returns'!$B$3:$S$61,0,ROW()-3)) -> 0.21782538 | ... S15: =CORREL(INDEX('Monthly Returns'!$B$3:$S$61,0,COLUMN()-1),INDEX('Monthly Returns'!$B$3:$S$61,0,ROW()-3)) -> 0.42381815
... A21: HON | B21: =CORREL(INDEX('Monthly Returns'!$B$3:$S$61,0,COLUMN()-1),INDEX('Monthly Returns'!$B$3:$S$61,0,ROW()-3)) -> 0.31800076 | C21: =CORREL(INDEX('Monthly Returns'!$B$3:$S$61,0,COLUMN()-1),INDEX('Monthly Returns'!$B$3:$S$61,0,ROW()-3)) -> 0.28351404 | D21: =CORREL(INDEX('Monthly Returns'!$B$3:$S$61,0,COLUMN()-1),INDEX('Monthly Returns'!$B$3:$S$61,0,ROW()-3)) -> 0.18500213 | E21: =CORREL(INDEX('Monthly Returns'!$B$3:$S$61,0,COLUMN()-1),INDEX('Monthly Returns'!$B$3:$S$61,0,ROW()-3)) -> 0.21223731 | F21: =CORREL(INDEX('Monthly Returns'!$B$3:$S$61,0,COLUMN()-1),INDEX('Monthly Returns'!$B$3:$S$61,0,ROW()-3)) -> 0.48584815 | G21: =CORREL(INDEX('Monthly Returns'!$B$3:$S$61,0,COLUMN()-1),INDEX('Monthly Returns'!$B$3:$S$61,0,ROW()-3)) -> 0.49861992 | H21: =CORREL(INDEX('Monthly Returns'!$B$3:$S$61,0,COLUMN()-1),INDEX('Monthly Returns'!$B$3:$S$61,0,ROW()-3)) -> 0.35227386 | I21: =CORREL(INDEX('Monthly Returns'!$B$3:$S$61,0,COLUMN()-1),INDEX('Monthly Returns'!$B$3:$S$61,0,ROW()-3)) -> 0.13015965 | ... S21: =CORREL(INDEX('Monthly Returns'!$B$3:$S$61,0,COLUMN()-1),INDEX('Monthly Returns'!$B$3:$S$61,0,ROW()-3)) -> 1

Sheet Covariance Matrix
A1: COVARIANCE MATRIX (Annualized)
B3: AAPL | C3: MSFT | D3: GOOGL | E3: AMZN | F3: JPM | G3: BAC | H3: JNJ | I3: UNH | J3: XOM | K3: CVX | L3: PG | M3: KO | N3: NEE | O3: DUK | P3: AMT | Q3: PLD | R3: CAT | S3: HON
A4: AAPL | B4: {=INDEX('Correlation Matrix'!$B$4:$S$21,ROW()-3,COLUMN()-1)*INDEX('Stock Analytics'!$G$5:$G$22,ROW()-3,1)*INDEX('Stock Analytics'!$G$5:$G$22,COLUMN()-1,1)} -> 0.059838306 | C4: {=INDEX('Correlation Matrix'!$B$4:$S$21,ROW()-3,COLUMN()-1)*INDEX('Stock Analytics'!$G$5:$G$22,ROW()-3,1)*INDEX('Stock Analytics'!$G$5:$G$22,COLUMN()-1,1)} -> 0.028265883 | D4: {=INDEX('Correlation Matrix'!$B$4:$S$21,ROW()-3,COLUMN()-1)*INDEX('Stock Analytics'!$G$5:$G$22,ROW()-3,1)*INDEX('Stock Analytics'!$G$5:$G$22,COLUMN()-1,1)} -> 0.033541201 | E4: {=INDEX('Correlation Matrix'!$B$4:$S$21,ROW()-3,COLUMN()-1)*INDEX('Stock Analytics'!$G$5:$G$22,ROW()-3,1)*INDEX('Stock Analytics'!$G$5:$G$22,COLUMN()-1,1)} -> 0.041220784 | F4: {=INDEX('Correlation Matrix'!$B$4:$S$21,ROW()-3,COLUMN()-1)*INDEX('Stock Analytics'!$G$5:$G$22,ROW()-3,1)*INDEX('Stock Analytics'!$G$5:$G$22,COLUMN()-1,1)} -> 0.013134486 | G4: {=INDEX('Correlation Matrix'!$B$4:$S$21,ROW()-3,COLUMN()-1)*INDEX('Stock Analytics'!$G$5:$G$22,ROW()-3,1)*INDEX('Stock Analytics'!$G$5:$G$22,COLUMN()-1,1)} -> 0.023346117 | H4: {=INDEX('Correlation Matrix'!$B$4:$S$21,ROW()-3,COLUMN()-1)*INDEX('Stock Analytics'!$G$5:$G$22,ROW()-3,1)*INDEX('Stock Analytics'!$G$5:$G$22,COLUMN()-1,1)} -> 0.0074825164 | I4: {=INDEX('Correlation Matrix'!$B$4:$S$21,ROW()-3,COLUMN()-1)*INDEX('Stock Analytics'!$G$5:$G$22,ROW()-3,1)*INDEX('Stock Analytics'!$G$5:$G$22,COLUMN()-1,1)} -> 0.023315737 | ... S4: {=INDEX('Correlation Matrix'!$B$4:$S$21,ROW()-3,COLUMN()-1)*INDEX('Stock Analytics'!$G$5:$G$22,ROW()-3,1)*INDEX('Stock Analytics'!$G$5:$G$22,COLUMN()-1,1)} -> 0.017070791
A5: MSFT | B5: {=INDEX('Correlation Matrix'!$B$4:$S$21,ROW()-3,COLUMN()-1)*INDEX('Stock Analytics'!$G$5:$G$22,ROW()-3,1)*INDEX('Stock Analytics'!$G$5:$G$22,COLUMN()-1,1)} -> 0.028265883 | C5: {=INDEX('Correlation Matrix'!$B$4:$S$21,ROW()-3,COLUMN()-1)*INDEX('Stock Analytics'!$G$5:$G$22,ROW()-3,1)*INDEX('Stock Analytics'!$G$5:$G$22,COLUMN()-1,1)} -> 0.056340688 | D5: {=INDEX('Correlation Matrix'!$B$4:$S$21,ROW()-3,COLUMN()-1)*INDEX('Stock Analytics'!$G$5:$G$22,ROW()-3,1)*INDEX('Stock Analytics'!$G$5:$G$22,COLUMN()-1,1)} -> 0.034934979 | E5: {=INDEX('Correlation Matrix'!$B$4:$S$21,ROW()-3,COLUMN()-1)*INDEX('Stock Analytics'!$G$5:$G$22,ROW()-3,1)*INDEX('Stock Analytics'!$G$5:$G$22,COLUMN()-1,1)} -> 0.047167962 | F5: {=INDEX('Correlation Matrix'!$B$4:$S$21,ROW()-3,COLUMN()-1)*INDEX('Stock Analytics'!$G$5:$G$22,ROW()-3,1)*INDEX('Stock Analytics'!$G$5:$G$22,COLUMN()-1,1)} -> 0.018171616 | G5: {=INDEX('Correlation Matrix'!$B$4:$S$21,ROW()-3,COLUMN()-1)*INDEX('Stock Analytics'!$G$5:$G$22,ROW()-3,1)*INDEX('Stock Analytics'!$G$5:$G$22,COLUMN()-1,1)} -> 0.02071214 | H5: {=INDEX('Correlation Matrix'!$B$4:$S$21,ROW()-3,COLUMN()-1)*INDEX('Stock Analytics'!$G$5:$G$22,ROW()-3,1)*INDEX('Stock Analytics'!$G$5:$G$22,COLUMN()-1,1)} -> -0.003100047 | I5: {=INDEX('Correlation Matrix'!$B$4:$S$21,ROW()-3,COLUMN()-1)*INDEX('Stock Analytics'!$G$5:$G$22,ROW()-3,1)*INDEX('Stock Analytics'!$G$5:$G$22,COLUMN()-1,1)} -> 0.00099623252 | ... S5: {=INDEX('Correlation Matrix'!$B$4:$S$21,ROW()-3,COLUMN()-1)*INDEX('Stock Analytics'!$G$5:$G$22,ROW()-3,1)*INDEX('Stock Analytics'!$G$5:$G$22,COLUMN()-1,1)} -> 0.014767993
A6: GOOGL | B6: {=INDEX('Correlation Matrix'!$B$4:$S$21,ROW()-3,COLUMN()-1)*INDEX('Stock Analytics'!$G$5:$G$22,ROW()-3,1)*INDEX('Stock Analytics'!$G$5:$G$22,COLUMN()-1,1)} -> 0.033541201 | C6: {=INDEX('Correlation Matrix'!$B$4:$S$21,ROW()-3,COLUMN()-1)*INDEX('Stock Analytics'!$G$5:$G$22,ROW()-3,1)*INDEX('Stock Analytics'!$G$5:$G$22,COLUMN()-1,1)} -> 0.034934979 | D6: {=INDEX('Correlation Matrix'!$B$4:$S$21,ROW()-3,COLUMN()-1)*INDEX('Stock Analytics'!$G$5:$G$22,ROW()-3,1)*INDEX('Stock Analytics'!$G$5:$G$22,COLUMN()-1,1)} -> 0.081311738 | E6: {=INDEX('Correlation Matrix'!$B$4:$S$21,ROW()-3,COLUMN()-1)*INDEX('Stock Analytics'!$G$5:$G$22,ROW()-3,1)*INDEX('Stock Analytics'!$G$5:$G$22,COLUMN()-1,1)} -> 0.05787062 | F6: {=INDEX('Correlation Matrix'!$B$4:$S$21,ROW()-3,COLUMN()-1)*INDEX('Stock Analytics'!$G$5:$G$22,ROW()-3,1)*INDEX('Stock Analytics'!$G$5:$G$22,COLUMN()-1,1)} -> 0.015746753 | G6: {=INDEX('Correlation Matrix'!$B$4:$S$21,ROW()-3,COLUMN()-1)*INDEX('Stock Analytics'!$G$5:$G$22,ROW()-3,1)*INDEX('Stock Analytics'!$G$5:$G$22,COLUMN()-1,1)} -> 0.025622517 | H6: {=INDEX('Correlation Matrix'!$B$4:$S$21,ROW()-3,COLUMN()-1)*INDEX('Stock Analytics'!$G$5:$G$22,ROW()-3,1)*INDEX('Stock Analytics'!$G$5:$G$22,COLUMN()-1,1)} -> 0.001321633 | I6: {=INDEX('Correlation Matrix'!$B$4:$S$21,ROW()-3,COLUMN()-1)*INDEX('Stock Analytics'!$G$5:$G$22,ROW()-3,1)*INDEX('Stock Analytics'!$G$5:$G$22,COLUMN()-1,1)} -> 0.0051996836 | ... S6: {=INDEX('Correlation Matrix'!$B$4:$S$21,ROW()-3,COLUMN()-1)*INDEX('Stock Analytics'!$G$5:$G$22,ROW()-3,1)*INDEX('Stock Analytics'!$G$5:$G$22,COLUMN()-1,1)} -> 0.011576818
A7: AMZN | B7: {=INDEX('Correlation Matrix'!$B$4:$S$21,ROW()-3,COLUMN()-1)*INDEX('Stock Analytics'!$G$5:$G$22,ROW()-3,1)*INDEX('Stock Analytics'!$G$5:$G$22,COLUMN()-1,1)} -> 0.041220784 | C7: {=INDEX('Correlation Matrix'!$B$4:$S$21,ROW()-3,COLUMN()-1)*INDEX('Stock Analytics'!$G$5:$G$22,ROW()-3,1)*INDEX('Stock Analytics'!$G$5:$G$22,COLUMN()-1,1)} -> 0.047167962 | D7: {=INDEX('Correlation Matrix'!$B$4:$S$21,ROW()-3,COLUMN()-1)*INDEX('Stock Analytics'!$G$5:$G$22,ROW()-3,1)*INDEX('Stock Analytics'!$G$5:$G$22,COLUMN()-1,1)} -> 0.05787062 | E7: {=INDEX('Correlation Matrix'!$B$4:$S$21,ROW()-3,COLUMN()-1)*INDEX('Stock Analytics'!$G$5:$G$22,ROW()-3,1)*INDEX('Stock Analytics'!$G$5:$G$22,COLUMN()-1,1)} -> 0.1020107 | F7: {=INDEX('Correlation Matrix'!$B$4:$S$21,ROW()-3,COLUMN()-1)*INDEX('Stock Analytics'!$G$5:$G$22,ROW()-3,1)*INDEX('Stock Analytics'!$G$5:$G$22,COLUMN()-1,1)} -> 0.0199463 | G7: {=INDEX('Correlation Matrix'!$B$4:$S$21,ROW()-3,COLUMN()-1)*INDEX('Stock Analytics'!$G$5:$G$22,ROW()-3,1)*INDEX('Stock Analytics'!$G$5:$G$22,COLUMN()-1,1)} -> 0.030625189 | H7: {=INDEX('Correlation Matrix'!$B$4:$S$21,ROW()-3,COLUMN()-1)*INDEX('Stock Analytics'!$G$5:$G$22,ROW()-3,1)*INDEX('Stock Analytics'!$G$5:$G$22,COLUMN()-1,1)} -> -0.010870884 | I7: {=INDEX('Correlation Matrix'!$B$4:$S$21,ROW()-3,COLUMN()-1)*INDEX('Stock Analytics'!$G$5:$G$22,ROW()-3,1)*INDEX('Stock Analytics'!$G$5:$G$22,COLUMN()-1,1)} -> -0.0056695867 | ... S7: {=INDEX('Correlation Matrix'!$B$4:$S$21,ROW()-3,COLUMN()-1)*INDEX('Stock Analytics'!$G$5:$G$22,ROW()-3,1)*INDEX('Stock Analytics'!$G$5:$G$22,COLUMN()-1,1)} -> 0.014875804
A8: JPM | B8: {=INDEX('Correlation Matrix'!$B$4:$S$21,ROW()-3,COLUMN()-1)*INDEX('Stock Analytics'!$G$5:$G$22,ROW()-3,1)*INDEX('Stock Analytics'!$G$5:$G$22,COLUMN()-1,1)} -> 0.013134486 | C8: {=INDEX('Correlation Matrix'!$B$4:$S$21,ROW()-3,COLUMN()-1)*INDEX('Stock Analytics'!$G$5:$G$22,ROW()-3,1)*INDEX('Stock Analytics'!$G$5:$G$22,COLUMN()-1,1)} -> 0.018171616 | D8: {=INDEX('Correlation Matrix'!$B$4:$S$21,ROW()-3,COLUMN()-1)*INDEX('Stock Analytics'!$G$5:$G$22,ROW()-3,1)*INDEX('Stock Analytics'!$G$5:$G$22,COLUMN()-1,1)} -> 0.015746753 | E8: {=INDEX('Correlation Matrix'!$B$4:$S$21,ROW()-3,COLUMN()-1)*INDEX('Stock Analytics'!$G$5:$G$22,ROW()-3,1)*INDEX('Stock Analytics'!$G$5:$G$22,COLUMN()-1,1)} -> 0.0199463 | F8: {=INDEX('Correlation Matrix'!$B$4:$S$21,ROW()-3,COLUMN()-1)*INDEX('Stock Analytics'!$G$5:$G$22,ROW()-3,1)*INDEX('Stock Analytics'!$G$5:$G$22,COLUMN()-1,1)} -> 0.056794455 | G8: {=INDEX('Correlation Matrix'!$B$4:$S$21,ROW()-3,COLUMN()-1)*INDEX('Stock Analytics'!$G$5:$G$22,ROW()-3,1)*INDEX('Stock Analytics'!$G$5:$G$22,COLUMN()-1,1)} -> 0.056099229 | H8: {=INDEX('Correlation Matrix'!$B$4:$S$21,ROW()-3,COLUMN()-1)*INDEX('Stock Analytics'!$G$5:$G$22,ROW()-3,1)*INDEX('Stock Analytics'!$G$5:$G$22,COLUMN()-1,1)} -> 0.0072475711 | I8: {=INDEX('Correlation Matrix'!$B$4:$S$21,ROW()-3,COLUMN()-1)*INDEX('Stock Analytics'!$G$5:$G$22,ROW()-3,1)*INDEX('Stock Analytics'!$G$5:$G$22,COLUMN()-1,1)} -> 0.010848895 | ... S8: {=INDEX('Correlation Matrix'!$B$4:$S$21,ROW()-3,COLUMN()-1)*INDEX('Stock Analytics'!$G$5:$G$22,ROW()-3,1)*INDEX('Stock Analytics'!$G$5:$G$22,COLUMN()-1,1)} -> 0.025409106
A9: BAC | B9: {=INDEX('Correlation Matrix'!$B$4:$S$21,ROW()-3,COLUMN()-1)*INDEX('Stock Analytics'!$G$5:$G$22,ROW()-3,1)*INDEX('Stock Analytics'!$G$5:$G$22,COLUMN()-1,1)} -> 0.023346117 | C9: {=INDEX('Correlation Matrix'!$B$4:$S$21,ROW()-3,COLUMN()-1)*INDEX('Stock Analytics'!$G$5:$G$22,ROW()-3,1)*INDEX('Stock Analytics'!$G$5:$G$22,COLUMN()-1,1)} -> 0.02071214 | D9: {=INDEX('Correlation Matrix'!$B$4:$S$21,ROW()-3,COLUMN()-1)*INDEX('Stock Analytics'!$G$5:$G$22,ROW()-3,1)*INDEX('Stock Analytics'!$G$5:$G$22,COLUMN()-1,1)} -> 0.025622517 | E9: {=INDEX('Correlation Matrix'!$B$4:$S$21,ROW()-3,COLUMN()-1)*INDEX('Stock Analytics'!$G$5:$G$22,ROW()-3,1)*INDEX('Stock Analytics'!$G$5:$G$22,COLUMN()-1,1)} -> 0.030625189 | F9: {=INDEX('Correlation Matrix'!$B$4:$S$21,ROW()-3,COLUMN()-1)*INDEX('Stock Analytics'!$G$5:$G$22,ROW()-3,1)*INDEX('Stock Analytics'!$G$5:$G$22,COLUMN()-1,1)} -> 0.056099229 | G9: {=INDEX('Correlation Matrix'!$B$4:$S$21,ROW()-3,COLUMN()-1)*INDEX('Stock Analytics'!$G$5:$G$22,ROW()-3,1)*INDEX('Stock Analytics'!$G$5:$G$22,COLUMN()-1,1)} -> 0.074506004 | H9: {=INDEX('Correlation Matrix'!$B$4:$S$21,ROW()-3,COLUMN()-1)*INDEX('Stock Analytics'!$G$5:$G$22,ROW()-3,1)*INDEX('Stock Analytics'!$G$5:$G$22,COLUMN()-1,1)} -> 0.0059140845 | I9: {=INDEX('Correlation Matrix'!$B$4:$S$21,ROW()-3,COLUMN()-1)*INDEX('Stock Analytics'!$G$5:$G$22,ROW()-3,1)*INDEX('Stock Analytics'!$G$5:$G$22,COLUMN()-1,1)} -> 0.017286185 | ... S9: {=INDEX('Correlation Matrix'!$B$4:$S$21,ROW()-3,COLUMN()-1)*INDEX('Stock Analytics'!$G$5:$G$22,ROW()-3,1)*INDEX('Stock Analytics'!$G$5:$G$22,COLUMN()-1,1)} -> 0.029867654
A10: JNJ | B10: {=INDEX('Correlation Matrix'!$B$4:$S$21,ROW()-3,COLUMN()-1)*INDEX('Stock Analytics'!$G$5:$G$22,ROW()-3,1)*INDEX('Stock Analytics'!$G$5:$G$22,COLUMN()-1,1)} -> 0.0074825164 | C10: {=INDEX('Correlation Matrix'!$B$4:$S$21,ROW()-3,COLUMN()-1)*INDEX('Stock Analytics'!$G$5:$G$22,ROW()-3,1)*INDEX('Stock Analytics'!$G$5:$G$22,COLUMN()-1,1)} -> -0.003100047 | D10: {=INDEX('Correlation Matrix'!$B$4:$S$21,ROW()-3,COLUMN()-1)*INDEX('Stock Analytics'!$G$5:$G$22,ROW()-3,1)*INDEX('Stock Analytics'!$G$5:$G$22,COLUMN()-1,1)} -> 0.001321633 | E10: {=INDEX('Correlation Matrix'!$B$4:$S$21,ROW()-3,COLUMN()-1)*INDEX('Stock Analytics'!$G$5:$G$22,ROW()-3,1)*INDEX('Stock Analytics'!$G$5:$G$22,COLUMN()-1,1)} -> -0.010870884 | F10: {=INDEX('Correlation Matrix'!$B$4:$S$21,ROW()-3,COLUMN()-1)*INDEX('Stock Analytics'!$G$5:$G$22,ROW()-3,1)*INDEX('Stock Analytics'!$G$5:$G$22,COLUMN()-1,1)} -> 0.0072475711 | G10: {=INDEX('Correlation Matrix'!$B$4:$S$21,ROW()-3,COLUMN()-1)*INDEX('Stock Analytics'!$G$5:$G$22,ROW()-3,1)*INDEX('Stock Analytics'!$G$5:$G$22,COLUMN()-1,1)} -> 0.0059140845 | H10: {=INDEX('Correlation Matrix'!$B$4:$S$21,ROW()-3,COLUMN()-1)*INDEX('Stock Analytics'!$G$5:$G$22,ROW()-3,1)*INDEX('Stock Analytics'!$G$5:$G$22,COLUMN()-1,1)} -> 0.028850891 | I10: {=INDEX('Correlation Matrix'!$B$4:$S$21,ROW()-3,COLUMN()-1)*INDEX('Stock Analytics'!$G$5:$G$22,ROW()-3,1)*INDEX('Stock Analytics'!$G$5:$G$22,COLUMN()-1,1)} -> 0.013564317 | ... S10: {=INDEX('Correlation Matrix'!$B$4:$S$21,ROW()-3,COLUMN()-1)*INDEX('Stock Analytics'!$G$5:$G$22,ROW()-3,1)*INDEX('Stock Analytics'!$G$5:$G$22,COLUMN()-1,1)} -> 0.013130942
A11: UNH | B11: {=INDEX('Correlation Matrix'!$B$4:$S$21,ROW()-3,COLUMN()-1)*INDEX('Stock Analytics'!$G$5:$G$22,ROW()-3,1)*INDEX('Stock Analytics'!$G$5:$G$22,COLUMN()-1,1)} -> 0.023315737 | C11: {=INDEX('Correlation Matrix'!$B$4:$S$21,ROW()-3,COLUMN()-1)*INDEX('Stock Analytics'!$G$5:$G$22,ROW()-3,1)*INDEX('Stock Analytics'!$G$5:$G$22,COLUMN()-1,1)} -> 0.00099623252 | D11: {=INDEX('Correlation Matrix'!$B$4:$S$21,ROW()-3,COLUMN()-1)*INDEX('Stock Analytics'!$G$5:$G$22,ROW()-3,1)*INDEX('Stock Analytics'!$G$5:$G$22,COLUMN()-1,1)} -> 0.0051996836 | E11: {=INDEX('Correlation Matrix'!$B$4:$S$21,ROW()-3,COLUMN()-1)*INDEX('Stock Analytics'!$G$5:$G$22,ROW()-3,1)*INDEX('Stock Analytics'!$G$5:$G$22,COLUMN()-1,1)} -> -0.0056695867 | F11: {=INDEX('Correlation Matrix'!$B$4:$S$21,ROW()-3,COLUMN()-1)*INDEX('Stock Analytics'!$G$5:$G$22,ROW()-3,1)*INDEX('Stock Analytics'!$G$5:$G$22,COLUMN()-1,1)} -> 0.010848895 | G11: {=INDEX('Correlation Matrix'!$B$4:$S$21,ROW()-3,COLUMN()-1)*INDEX('Stock Analytics'!$G$5:$G$22,ROW()-3,1)*INDEX('Stock Analytics'!$G$5:$G$22,COLUMN()-1,1)} -> 0.017286185 | H11: {=INDEX('Correlation Matrix'!$B$4:$S$21,ROW()-3,COLUMN()-1)*INDEX('Stock Analytics'!$G$5:$G$22,ROW()-3,1)*INDEX('Stock Analytics'!$G$5:$G$22,COLUMN()-1,1)} -> 0.013564317 | I11: {=INDEX('Correlation Matrix'!$B$4:$S$21,ROW()-3,COLUMN()-1)*INDEX('Stock Analytics'!$G$5:$G$22,ROW()-3,1)*INDEX('Stock Analytics'!$G$5:$G$22,COLUMN()-1,1)} -> 0.093478673 | ... S11: {=INDEX('Correlation Matrix'!$B$4:$S$21,ROW()-3,COLUMN()-1)*INDEX('Stock Analytics'!$G$5:$G$22,ROW()-3,1)*INDEX('Stock Analytics'!$G$5:$G$22,COLUMN()-1,1)} -> 0.0087331015
A12: XOM | B12: {=INDEX('Correlation Matrix'!$B$4:$S$21,ROW()-3,COLUMN()-1)*INDEX('Stock Analytics'!$G$5:$G$22,ROW()-3,1)*INDEX('Stock Analytics'!$G$5:$G$22,COLUMN()-1,1)} -> 0.0040902877 | C12: {=INDEX('Correlation Matrix'!$B$4:$S$21,ROW()-3,COLUMN()-1)*INDEX('Stock Analytics'!$G$5:$G$22,ROW()-3,1)*INDEX('Stock Analytics'!$G$5:$G$22,COLUMN()-1,1)} -> -0.010138142 | D12: {=INDEX('Correlation Matrix'!$B$4:$S$21,ROW()-3,COLUMN()-1)*INDEX('Stock Analytics'!$G$5:$G$22,ROW()-3,1)*INDEX('Stock Analytics'!$G$5:$G$22,COLUMN()-1,1)} -> -0.0078337475 | E12: {=INDEX('Correlation Matrix'!$B$4:$S$21,ROW()-3,COLUMN()-1)*INDEX('Stock Analytics'!$G$5:$G$22,ROW()-3,1)*INDEX('Stock Analytics'!$G$5:$G$22,COLUMN()-1,1)} -> -0.0062329146 | F12: {=INDEX('Correlation Matrix'!$B$4:$S$21,ROW()-3,COLUMN()-1)*INDEX('Stock Analytics'!$G$5:$G$22,ROW()-3,1)*INDEX('Stock Analytics'!$G$5:$G$22,COLUMN()-1,1)} -> 0.01376699 | G12: {=INDEX('Correlation Matrix'!$B$4:$S$21,ROW()-3,COLUMN()-1)*INDEX('Stock Analytics'!$G$5:$G$22,ROW()-3,1)*INDEX('Stock Analytics'!$G$5:$G$22,COLUMN()-1,1)} -> 0.025551873 | H12: {=INDEX('Correlation Matrix'!$B$4:$S$21,ROW()-3,COLUMN()-1)*INDEX('Stock Analytics'!$G$5:$G$22,ROW()-3,1)*INDEX('Stock Analytics'!$G$5:$G$22,COLUMN()-1,1)} -> 0.012919473 | I12: {=INDEX('Correlation Matrix'!$B$4:$S$21,ROW()-3,COLUMN()-1)*INDEX('Stock Analytics'!$G$5:$G$22,ROW()-3,1)*INDEX('Stock Analytics'!$G$5:$G$22,COLUMN()-1,1)} -> 0.013321559 | ... S12: {=INDEX('Correlation Matrix'!$B$4:$S$21,ROW()-3,COLUMN()-1)*INDEX('Stock Analytics'!$G$5:$G$22,ROW()-3,1)*INDEX('Stock Analytics'!$G$5:$G$22,COLUMN()-1,1)} -> 0.024822775
A13: CVX | B13: {=INDEX('Correlation Matrix'!$B$4:$S$21,ROW()-3,COLUMN()-1)*INDEX('Stock Analytics'!$G$5:$G$22,ROW()-3,1)*INDEX('Stock Analytics'!$G$5:$G$22,COLUMN()-1,1)} -> 0.011358511 | C13: {=INDEX('Correlation Matrix'!$B$4:$S$21,ROW()-3,COLUMN()-1)*INDEX('Stock Analytics'!$G$5:$G$22,ROW()-3,1)*INDEX('Stock Analytics'!$G$5:$G$22,COLUMN()-1,1)} -> -0.0028544249 | D13: {=INDEX('Correlation Matrix'!$B$4:$S$21,ROW()-3,COLUMN()-1)*INDEX('Stock Analytics'!$G$5:$G$22,ROW()-3,1)*INDEX('Stock Analytics'!$G$5:$G$22,COLUMN()-1,1)} -> 0.0006872124 | E13: {=INDEX('Correlation Matrix'!$B$4:$S$21,ROW()-3,COLUMN()-1)*INDEX('Stock Analytics'!$G$5:$G$22,ROW()-3,1)*INDEX('Stock Analytics'!$G$5:$G$22,COLUMN()-1,1)} -> 0.0060171853 | F13: {=INDEX('Correlation Matrix'!$B$4:$S$21,ROW()-3,COLUMN()-1)*INDEX('Stock Analytics'!$G$5:$G$22,ROW()-3,1)*INDEX('Stock Analytics'!$G$5:$G$22,COLUMN()-1,1)} -> 0.022190143 | G13: {=INDEX('Correlation Matrix'!$B$4:$S$21,ROW()-3,COLUMN()-1)*INDEX('Stock Analytics'!$G$5:$G$22,ROW()-3,1)*INDEX('Stock Analytics'!$G$5:$G$22,COLUMN()-1,1)} -> 0.03252823 | H13: {=INDEX('Correlation Matrix'!$B$4:$S$21,ROW()-3,COLUMN()-1)*INDEX('Stock Analytics'!$G$5:$G$22,ROW()-3,1)*INDEX('Stock Analytics'!$G$5:$G$22,COLUMN()-1,1)} -> 0.017066452 | I13: {=INDEX('Correlation Matrix'!$B$4:$S$21,ROW()-3,COLUMN()-1)*INDEX('Stock Analytics'!$G$5:$G$22,ROW()-3,1)*INDEX('Stock Analytics'!$G$5:$G$22,COLUMN()-1,1)} -> 0.02160492 | ... S13: {=INDEX('Correlation Matrix'!$B$4:$S$21,ROW()-3,COLUMN()-1)*INDEX('Stock Analytics'!$G$5:$G$22,ROW()-3,1)*INDEX('Stock Analytics'!$G$5:$G$22,COLUMN()-1,1)} -> 0.030531935
A14: PG | B14: {=INDEX('Correlation Matrix'!$B$4:$S$21,ROW()-3,COLUMN()-1)*INDEX('Stock Analytics'!$G$5:$G$22,ROW()-3,1)*INDEX('Stock Analytics'!$G$5:$G$22,COLUMN()-1,1)} -> 0.0074253951 | C14: {=INDEX('Correlation Matrix'!$B$4:$S$21,ROW()-3,COLUMN()-1)*INDEX('Stock Analytics'!$G$5:$G$22,ROW()-3,1)*INDEX('Stock Analytics'!$G$5:$G$22,COLUMN()-1,1)} -> 0.006380538 | D14: {=INDEX('Correlation Matrix'!$B$4:$S$21,ROW()-3,COLUMN()-1)*INDEX('Stock Analytics'!$G$5:$G$22,ROW()-3,1)*INDEX('Stock Analytics'!$G$5:$G$22,COLUMN()-1,1)} -> -0.0039300381 | E14: {=INDEX('Correlation Matrix'!$B$4:$S$21,ROW()-3,COLUMN()-1)*INDEX('Stock Analytics'!$G$5:$G$22,ROW()-3,1)*INDEX('Stock Analytics'!$G$5:$G$22,COLUMN()-1,1)} -> -0.009228625 | F14: {=INDEX('Correlation Matrix'!$B$4:$S$21,ROW()-3,COLUMN()-1)*INDEX('Stock Analytics'!$G$5:$G$22,ROW()-3,1)*INDEX('Stock Analytics'!$G$5:$G$22,COLUMN()-1,1)} -> 0.005874289 | G14: {=INDEX('Correlation Matrix'!$B$4:$S$21,ROW()-3,COLUMN()-1)*INDEX('Stock Analytics'!$G$5:$G$22,ROW()-3,1)*INDEX('Stock Analytics'!$G$5:$G$22,COLUMN()-1,1)} -> 0.0057335735 | H14: {=INDEX('Correlation Matrix'!$B$4:$S$21,ROW()-3,COLUMN()-1)*INDEX('Stock Analytics'!$G$5:$G$22,ROW()-3,1)*INDEX('Stock Analytics'!$G$5:$G$22,COLUMN()-1,1)} -> 0.012893719 | I14: {=INDEX('Correlation Matrix'!$B$4:$S$21,ROW()-3,COLUMN()-1)*INDEX('Stock Analytics'!$G$5:$G$22,ROW()-3,1)*INDEX('Stock Analytics'!$G$5:$G$22,COLUMN()-1,1)} -> 0.010586871 | ... S14: {=INDEX('Correlation Matrix'!$B$4:$S$21,ROW()-3,COLUMN()-1)*INDEX('Stock Analytics'!$G$5:$G$22,ROW()-3,1)*INDEX('Stock Analytics'!$G$5:$G$22,COLUMN()-1,1)} -> 0.01765353
A15: KO | B15: {=INDEX('Correlation Matrix'!$B$4:$S$21,ROW()-3,COLUMN()-1)*INDEX('Stock Analytics'!$G$5:$G$22,ROW()-3,1)*INDEX('Stock Analytics'!$G$5:$G$22,COLUMN()-1,1)} -> 0.0091299603 | C15: {=INDEX('Correlation Matrix'!$B$4:$S$21,ROW()-3,COLUMN()-1)*INDEX('Stock Analytics'!$G$5:$G$22,ROW()-3,1)*INDEX('Stock Analytics'!$G$5:$G$22,COLUMN()-1,1)} -> 0.0027328328 | D15: {=INDEX('Correlation Matrix'!$B$4:$S$21,ROW()-3,COLUMN()-1)*INDEX('Stock Analytics'!$G$5:$G$22,ROW()-3,1)*INDEX('Stock Analytics'!$G$5:$G$22,COLUMN()-1,1)} -> 0.0017541271 | E15: {=INDEX('Correlation Matrix'!$B$4:$S$21,ROW()-3,COLUMN()-1)*INDEX('Stock Analytics'!$G$5:$G$22,ROW()-3,1)*INDEX('Stock Analytics'!$G$5:$G$22,COLUMN()-1,1)} -> -0.0091684611 | F15: {=INDEX('Correlation Matrix'!$B$4:$S$21,ROW()-3,COLUMN()-1)*INDEX('Stock Analytics'!$G$5:$G$22,ROW()-3,1)*INDEX('Stock Analytics'!$G$5:$G$22,COLUMN()-1,1)} -> 0.0042922157 | G15: {=INDEX('Correlation Matrix'!$B$4:$S$21,ROW()-3,COLUMN()-1)*INDEX('Stock Analytics'!$G$5:$G$22,ROW()-3,1)*INDEX('Stock Analytics'!$G$5:$G$22,COLUMN()-1,1)} -> 0.0076679063 | H15: {=INDEX('Correlation Matrix'!$B$4:$S$21,ROW()-3,COLUMN()-1)*INDEX('Stock Analytics'!$G$5:$G$22,ROW()-3,1)*INDEX('Stock Analytics'!$G$5:$G$22,COLUMN()-1,1)} -> 0.016790446 | I15: {=INDEX('Correlation Matrix'!$B$4:$S$21,ROW()-3,COLUMN()-1)*INDEX('Stock Analytics'!$G$5:$G$22,ROW()-3,1)*INDEX('Stock Analytics'!$G$5:$G$22,COLUMN()-1,1)} -> 0.011208124 | ... S15: {=INDEX('Correlation Matrix'!$B$4:$S$21,ROW()-3,COLUMN()-1)*INDEX('Stock Analytics'!$G$5:$G$22,ROW()-3,1)*INDEX('Stock Analytics'!$G$5:$G$22,COLUMN()-1,1)} -> 0.015652495
... A21: HON | B21: {=INDEX('Correlation Matrix'!$B$4:$S$21,ROW()-3,COLUMN()-1)*INDEX('Stock Analytics'!$G$5:$G$22,ROW()-3,1)*INDEX('Stock Analytics'!$G$5:$G$22,COLUMN()-1,1)} -> 0.017070791 | C21: {=INDEX('Correlation Matrix'!$B$4:$S$21,ROW()-3,COLUMN()-1)*INDEX('Stock Analytics'!$G$5:$G$22,ROW()-3,1)*INDEX('Stock Analytics'!$G$5:$G$22,COLUMN()-1,1)} -> 0.014767993 | D21: {=INDEX('Correlation Matrix'!$B$4:$S$21,ROW()-3,COLUMN()-1)*INDEX('Stock Analytics'!$G$5:$G$22,ROW()-3,1)*INDEX('Stock Analytics'!$G$5:$G$22,COLUMN()-1,1)} -> 0.011576818 | E21: {=INDEX('Correlation Matrix'!$B$4:$S$21,ROW()-3,COLUMN()-1)*INDEX('Stock Analytics'!$G$5:$G$22,ROW()-3,1)*INDEX('Stock Analytics'!$G$5:$G$22,COLUMN()-1,1)} -> 0.014875804 | F21: {=INDEX('Correlation Matrix'!$B$4:$S$21,ROW()-3,COLUMN()-1)*INDEX('Stock Analytics'!$G$5:$G$22,ROW()-3,1)*INDEX('Stock Analytics'!$G$5:$G$22,COLUMN()-1,1)} -> 0.025409106 | G21: {=INDEX('Correlation Matrix'!$B$4:$S$21,ROW()-3,COLUMN()-1)*INDEX('Stock Analytics'!$G$5:$G$22,ROW()-3,1)*INDEX('Stock Analytics'!$G$5:$G$22,COLUMN()-1,1)} -> 0.029867654 | H21: {=INDEX('Correlation Matrix'!$B$4:$S$21,ROW()-3,COLUMN()-1)*INDEX('Stock Analytics'!$G$5:$G$22,ROW()-3,1)*INDEX('Stock Analytics'!$G$5:$G$22,COLUMN()-1,1)} -> 0.013130942 | I21: {=INDEX('Correlation Matrix'!$B$4:$S$21,ROW()-3,COLUMN()-1)*INDEX('Stock Analytics'!$G$5:$G$22,ROW()-3,1)*INDEX('Stock Analytics'!$G$5:$G$22,COLUMN()-1,1)} -> 0.0087331015 | ... S21: {=INDEX('Correlation Matrix'!$B$4:$S$21,ROW()-3,COLUMN()-1)*INDEX('Stock Analytics'!$G$5:$G$22,ROW()-3,1)*INDEX('Stock Analytics'!$G$5:$G$22,COLUMN()-1,1)} -> 0.048158361

Sheet Portfolio Optimizer
A1: PORTFOLIO OPTIMIZER — MAX SHARPE RATIO
A2: Risk-Free Rate | B2: 0.0425
A4: Ticker | B4: Expected Return | C4: Annualized Volatility | D4: Weight | E4: Min Weight | F4: Max Weight | G4: Weighted Return | I4: MAX SHARPE | J4: MIN VARIANCE | K4: EQUAL WEIGHT
A5: AAPL | B5: 0.212 | C5: 0.2446 | D5: =1/18 -> 0.055555556 | E5: 0 | F5: 0.3 | G5: =D5*B5 -> 0.011777778 | I5: 0 | J5: 0 | K5: =1/18 -> 0.055555556
A6: MSFT | B6: 0.1073 | C6: 0.2374 | D6: =1/18 -> 0.055555556 | E6: 0 | F6: 0.3 | G6: =D6*B6 -> 0.0059611111 | I6: 0 | J6: 0.084128411 | K6: =1/18 -> 0.055555556
A7: GOOGL | B7: 0.0083 | C7: 0.2852 | D7: =1/18 -> 0.055555556 | E7: 0 | F7: 0.3 | G7: =D7*B7 -> 0.00046111111 | I7: 0 | J7: 0.029819767 | K7: =1/18 -> 0.055555556
A8: AMZN | B8: 0.3043 | C8: 0.3194 | D8: =1/18 -> 0.055555556 | E8: 0 | F8: 0.3 | G8: =D8*B8 -> 0.016905556 | I8: 0.2115 | J8: 0.11584778 | K8: =1/18 -> 0.055555556
A9: JPM | B9: 0.0841 | C9: 0.2383 | D9: =1/18 -> 0.055555556 | E9: 0 | F9: 0.3 | G9: =D9*B9 -> 0.0046722222 | I9: 0 | J9: 0.04252565 | K9: =1/18 -> 0.055555556
A10: BAC | B10: 0.1129 | C10: 0.273 | D10: =1/18 -> 0.055555556 | E10: 0 | F10: 0.3 | G10: =D10*B10 -> 0.0062722222 | I10: 0 | J10: 0 | K10: =1/18 -> 0.055555556
A11: JNJ | B11: 0.213 | C11: 0.1699 | D11: =1/18 -> 0.055555556 | E11: 0 | F11: 0.3 | G11: =D11*B11 -> 0.011833333 | I11: 0.3 | J11: 0.23142578 | K11: =1/18 -> 0.055555556
A12: UNH | B12: 0.3691 | C12: 0.3057 | D12: =1/18 -> 0.055555556 | E12: 0 | F12: 0.3 | G12: =D12*B12 -> 0.020505556 | I12: 0.2239 | J12: 0.037091271 | K12: =1/18 -> 0.055555556
A13: XOM | B13: 0.0807 | C13: 0.2657 | D13: =1/18 -> 0.055555556 | E13: 0 | F13: 0.3 | G13: =D13*B13 -> 0.0044833333 | I13: 0 | J13: 0.093454439 | K13: =1/18 -> 0.055555556
A14: CVX | B14: 0.1245 | C14: 0.2707 | D14: =1/18 -> 0.055555556 | E14: 0 | F14: 0.3 | G14: =D14*B14 -> 0.0069166667 | I14: 0 | J14: 0 | K14: =1/18 -> 0.055555556
A15: PG | B15: 0.0178 | C15: 0.1748 | D15: =1/18 -> 0.055555556 | E15: 0 | F15: 0.3 | G15: =D15*B15 -> 0.00098888889 | I15: 0 | J15: 0.20803182 | K15: =1/18 -> 0.055555556
A16: KO | B16: 0.1394 | C16: 0.1683 | D16: =1/18 -> 0.055555556 | E16: 0 | F16: 0.3 | G16: =D16*B16 -> 0.0077444444 | I16: 0 | J16: 0.069407952 | K16: =1/18 -> 0.055555556
... A22: HON | B22: 0.3144 | C22: 0.2195 | D22: =1/18 -> 0.055555556 | E22: 0 | F22: 0.3 | G22: =D22*B22 -> 0.017466667 | I22: 0.2646 | J22: 0 | K22: =1/18 -> 0.055555556
A27: PORTFOLIO STATISTICS
A28: Portfolio Return: | B28: =SUM(G5:G22) -> 0.15716667 | I28: 0.294 | J28: 0.1437 | K28: 0.1572
A29: Portfolio Variance: | B29: =SUMPRODUCT(D5:D22,MMULT('Covariance Matrix'!B4:S21,D5:D22)) -> 0.02071588
A30: Portfolio Volatility: | B30: =SQRT(B29) -> 0.14393012 | I30: 0.1411 | J30: 0.1114 | K30: 0.1439
A31: Risk-Free Rate: | B31: =B2 -> 0.0425
A32: Sharpe Ratio: | B32: =(B28-B31)/B30 -> 0.79668289 | I32: 1.7831 | J32: 0.9081 | K32: 0.7967
A33: Sum of Weights: | B33: =SUM(D5:D22) -> 1
A35: CONSTRAINTS
A36: Weights sum to exactly: | B36: 1
A37: Minimum per stock: | B37: 0
A38: Maximum per stock: | B38: 0.3

Sheet Efficient Frontier
A1: EFFICIENT FRONTIER — 18 STOCK PORTFOLIO (Mar 2021 – Feb 2026)
A3: Point | B3: Target Return | C3: Min Volatility | D3: Sharpe Ratio | E3: Portfolio Type
A4: 1 | B4: 0.08 | C4: 0.128 | D4: 0.2929
A5: 2 | B5: 0.09 | C5: 0.1213 | D5: 0.3914
A6: 3 | B6: 0.1 | C6: 0.1164 | D6: 0.4938
A7: 4 | B7: 0.11 | C7: 0.114 | D7: 0.5919
A8: 5 | B8: 0.12 | C8: 0.1125 | D8: 0.6891
A9: 6 | B9: 0.13 | C9: 0.1117 | D9: 0.7837
A10: 7 | B10: 0.14 | C10: 0.1114 | D10: 0.8752
A11: 8 | B11: 0.15 | C11: 0.1116 | D11: 0.9633 | E11: Min Variance
A12: 9 | B12: 0.16 | C12: 0.1122 | D12: 1.0468
A13: 10 | B13: 0.17 | C13: 0.1133 | D13: 1.1249 | E13: Equal Weight
A14: 11 | B14: 0.18 | C14: 0.1149 | D14: 1.1971
A15: 12 | B15: 0.19 | C15: 0.1168 | D15: 1.2626
A16: 13 | B16: 0.2 | C16: 0.1192 | D16: 1.321
A17: 14 | B17: 0.21 | C17: 0.1222 | D17: 1.3708
A18: 15 | B18: 0.22 | C18: 0.1259 | D18: 1.4101
A19: 16 | B19: 0.23 | C19: 0.1302 | D19: 1.4399
A20: 17 | B20: 0.24 | C20: 0.1352 | D20: 1.4612
A21: 18 | B21: 0.25 | C21: 0.1409 | D21: 1.4724
A22: 19 | B22: 0.26 | C22: 0.1473 | D22: 1.4764 | E22: Max Sharpe
A23: 20 | B23: 0.27 | C23: 0.1544 | D23: 1.4738
A24: 21 | B24: 0.28 | C24: 0.1622 | D24: 1.4645
A25: 22 | B25: 0.29 | C25: 0.1708 | D25: 1.449
A26: 23 | B26: 0.3 | C26: 0.1801 | D26: 1.4295
A27: 24 | B27: 0.31 | C27: 0.19 | D27: 1.4075
A28: 25 | B28: 0.32 | C28: 0.2006 | D28: 1.3834
A29: 26 | B29: 0.33 | C29: 0.212 | D29: 1.3585
A30: 27 | B30: 0.34 | C30: 0.2241 | D30: 1.3293
A31: 28 | B31: 0.35 | C31: 0.237 | D31: 1.2975
A32: 29 | B32: 0.36 | C32: 0.2507 | D32: 1.264
A33: 30 | B33: 0.37 | C33: 0.2651 | D33: 1.2259

Sheet Portfolio Weights
A1: Ticker | B1: Portfolio | C1: Weight
A2: AAPL | B2: Max Sharpe | C2: 0
A3: MSFT | B3: Max Sharpe | C3: 0
A4: GOOGL | B4: Max Sharpe | C4: 0.3
A5: AMZN | B5: Max Sharpe | C5: 0
A6: JPM | B6: Max Sharpe | C6: 0.1015
A7: BAC | B7: Max Sharpe | C7: 0
A8: JNJ | B8: Max Sharpe | C8: 0.0414
A9: UNH | B9: Max Sharpe | C9: 0
A10: XOM | B10: Max Sharpe | C10: 0.3
A11: CVX | B11: Max Sharpe | C11: 0
A12: PG | B12: Max Sharpe | C12: 0
A13: KO | B13: Max Sharpe | C13: 0.1642
... A55: HON | B55: Equal Weight | C55: 0.0556

Sheet Stock Data
A1: Ticker | B1: Company | C1: Sector | D1: Ann_Return | E1: Ann_Volatility | F1: Sharpe_Ratio | G1: Beta
A2: AAPL | B2: Apple Inc. | C2: Technology | D2: 0.212 | E2: 0.2446 | F2: 0.6931 | G2: 1.2
A3: MSFT | B3: Microsoft Corp. | C3: Technology | D3: 0.1442 | E3: 0.2374 | F3: 0.4286 | G3: 1.1
A4: GOOGL | B4: Alphabet Inc. | C4: Technology | D4: 0.3043 | E4: 0.2852 | F4: 0.9181 | G4: 1.15
A5: AMZN | B5: Amazon.com Inc. | C5: Consumer Disc. | D5: 0.1129 | E5: 0.3194 | F5: 0.2204 | G5: 1.3
A6: JPM | B6: JPMorgan Chase | C6: Financials | D6: 0.2085 | E6: 0.2383 | F6: 0.6965 | G6: 1.25
A7: BAC | B7: Bank of America | C7: Financials | D7: 0.1245 | E7: 0.273 | F7: 0.3005 | G7: 1.35
A8: JNJ | B8: Johnson & Johnson | C8: Healthcare | D8: 0.1314 | E8: 0.1699 | F8: 0.5232 | G8: 0.65
A9: UNH | B9: UnitedHealth Group | C9: Healthcare | D9: 0.0083 | E9: 0.3057 | F9: -0.112 | G9: 0.8
A10: XOM | B10: Exxon Mobil | C10: Energy | D10: 0.3144 | E10: 0.2657 | F10: 1.0234 | G10: 0.95
A11: CVX | B11: Chevron Corp. | C11: Energy | D11: 0.213 | E11: 0.2707 | F11: 0.6297 | G11: 0.9
A12: PG | B12: Procter & Gamble | C12: Consumer Staples | D12: 0.0841 | E12: 0.1748 | F12: 0.2379 | G12: 0.55
A13: KO | B13: Coca-Cola Co. | C13: Consumer Staples | D13: 0.1394 | E13: 0.1683 | F13: 0.5756 | G13: 0.52
... A19: HON | B19: Honeywell Intl. | C19: Industrials | D19: 0.0807 | E19: 0.2195 | F19: 0.174 | G19: 1.05

Sheet Portfolio Summary
A1: Portfolio | B1: Return | C1: Volatility | D1: Sharpe
A2: Ma xSharpe | B2: 0.2611 | C2: 0.1481 | D2: 1.4764
A3: Min Variance | B3: 0.15 | C3: 0.1116 | D3: 0.9633
A4: Equal Weight | B4: 0.1572 | C4: 0.1439 | D4: 0.7967

Sheet Monte Carlo
